2020-01-17 08:59:36,328 ERROR: Exception on / [GET] [in /Users/wouterlefebvre/Github Repo's/FaceRec/FaceRecVenv/lib/python3.6/site-packages/flask/app.py:1891]
Traceback (most recent call last):
  File "/Users/wouterlefebvre/Github Repo's/FaceRec/FaceRecVenv/lib/python3.6/site-packages/sqlalchemy/engine/base.py", line 2276, in _wrap_pool_connect
    return fn()
  File "/Users/wouterlefebvre/Github Repo's/FaceRec/FaceRecVenv/lib/python3.6/site-packages/sqlalchemy/pool/base.py", line 363, in connect
    return _ConnectionFairy._checkout(self)
  File "/Users/wouterlefebvre/Github Repo's/FaceRec/FaceRecVenv/lib/python3.6/site-packages/sqlalchemy/pool/base.py", line 760, in _checkout
    fairy = _ConnectionRecord.checkout(pool)
  File "/Users/wouterlefebvre/Github Repo's/FaceRec/FaceRecVenv/lib/python3.6/site-packages/sqlalchemy/pool/base.py", line 492, in checkout
    rec = pool._do_get()
  File "/Users/wouterlefebvre/Github Repo's/FaceRec/FaceRecVenv/lib/python3.6/site-packages/sqlalchemy/pool/impl.py", line 139, in _do_get
    self._dec_overflow()
  File "/Users/wouterlefebvre/Github Repo's/FaceRec/FaceRecVenv/lib/python3.6/site-packages/sqlalchemy/util/langhelpers.py", line 68, in __exit__
    compat.reraise(exc_type, exc_value, exc_tb)
  File "/Users/wouterlefebvre/Github Repo's/FaceRec/FaceRecVenv/lib/python3.6/site-packages/sqlalchemy/util/compat.py", line 153, in reraise
    raise value
  File "/Users/wouterlefebvre/Github Repo's/FaceRec/FaceRecVenv/lib/python3.6/site-packages/sqlalchemy/pool/impl.py", line 136, in _do_get
    return self._create_connection()
  File "/Users/wouterlefebvre/Github Repo's/FaceRec/FaceRecVenv/lib/python3.6/site-packages/sqlalchemy/pool/base.py", line 308, in _create_connection
    return _ConnectionRecord(self)
  File "/Users/wouterlefebvre/Github Repo's/FaceRec/FaceRecVenv/lib/python3.6/site-packages/sqlalchemy/pool/base.py", line 437, in __init__
    self.__connect(first_connect_check=True)
  File "/Users/wouterlefebvre/Github Repo's/FaceRec/FaceRecVenv/lib/python3.6/site-packages/sqlalchemy/pool/base.py", line 639, in __connect
    connection = pool._invoke_creator(self)
  File "/Users/wouterlefebvre/Github Repo's/FaceRec/FaceRecVenv/lib/python3.6/site-packages/sqlalchemy/engine/strategies.py", line 114, in connect
    return dialect.connect(*cargs, **cparams)
  File "/Users/wouterlefebvre/Github Repo's/FaceRec/FaceRecVenv/lib/python3.6/site-packages/sqlalchemy/engine/default.py", line 482, in connect
    return self.dbapi.connect(*cargs, **cparams)
pyodbc.OperationalError: ('HYT00', '[HYT00] [Microsoft][ODBC Driver 13 for SQL Server]Login timeout expired (0) (SQLDriverConnect)')

The above exception was the direct cause of the following exception:

Traceback (most recent call last):
  File "/Users/wouterlefebvre/Github Repo's/FaceRec/FaceRecVenv/lib/python3.6/site-packages/flask/app.py", line 2446, in wsgi_app
    response = self.full_dispatch_request()
  File "/Users/wouterlefebvre/Github Repo's/FaceRec/FaceRecVenv/lib/python3.6/site-packages/flask/app.py", line 1951, in full_dispatch_request
    rv = self.handle_user_exception(e)
  File "/Users/wouterlefebvre/Github Repo's/FaceRec/FaceRecVenv/lib/python3.6/site-packages/flask/app.py", line 1820, in handle_user_exception
    reraise(exc_type, exc_value, tb)
  File "/Users/wouterlefebvre/Github Repo's/FaceRec/FaceRecVenv/lib/python3.6/site-packages/flask/_compat.py", line 39, in reraise
    raise value
  File "/Users/wouterlefebvre/Github Repo's/FaceRec/FaceRecVenv/lib/python3.6/site-packages/flask/app.py", line 1949, in full_dispatch_request
    rv = self.dispatch_request()
  File "/Users/wouterlefebvre/Github Repo's/FaceRec/FaceRecVenv/lib/python3.6/site-packages/flask/app.py", line 1935, in dispatch_request
    return self.view_functions[rule.endpoint](**req.view_args)
  File "/Users/wouterlefebvre/Github Repo's/FaceRec/application/routes.py", line 111, in index
    return render_template('index.html')
  File "/Users/wouterlefebvre/Github Repo's/FaceRec/FaceRecVenv/lib/python3.6/site-packages/flask/templating.py", line 136, in render_template
    ctx.app.update_template_context(context)
  File "/Users/wouterlefebvre/Github Repo's/FaceRec/FaceRecVenv/lib/python3.6/site-packages/flask/app.py", line 838, in update_template_context
    context.update(func())
  File "/Users/wouterlefebvre/Github Repo's/FaceRec/FaceRecVenv/lib/python3.6/site-packages/flask_login/utils.py", line 368, in _user_context_processor
    return dict(current_user=_get_user())
  File "/Users/wouterlefebvre/Github Repo's/FaceRec/FaceRecVenv/lib/python3.6/site-packages/flask_login/utils.py", line 335, in _get_user
    current_app.login_manager._load_user()
  File "/Users/wouterlefebvre/Github Repo's/FaceRec/FaceRecVenv/lib/python3.6/site-packages/flask_login/login_manager.py", line 353, in _load_user
    return self._load_from_cookie(request.cookies[cookie_name])
  File "/Users/wouterlefebvre/Github Repo's/FaceRec/FaceRecVenv/lib/python3.6/site-packages/flask_login/login_manager.py", line 392, in _load_from_cookie
    self.reload_user()
  File "/Users/wouterlefebvre/Github Repo's/FaceRec/FaceRecVenv/lib/python3.6/site-packages/flask_login/login_manager.py", line 321, in reload_user
    user = self.user_callback(user_id)
  File "/Users/wouterlefebvre/Github Repo's/FaceRec/application/models.py", line 23, in load_user
    return User.query.get(int(id))
  File "/Users/wouterlefebvre/Github Repo's/FaceRec/FaceRecVenv/lib/python3.6/site-packages/sqlalchemy/orm/query.py", line 982, in get
    return self._get_impl(ident, loading.load_on_pk_identity)
  File "/Users/wouterlefebvre/Github Repo's/FaceRec/FaceRecVenv/lib/python3.6/site-packages/sqlalchemy/orm/query.py", line 1094, in _get_impl
    return db_load_fn(self, primary_key_identity)
  File "/Users/wouterlefebvre/Github Repo's/FaceRec/FaceRecVenv/lib/python3.6/site-packages/sqlalchemy/orm/loading.py", line 284, in load_on_pk_identity
    return q.one()
  File "/Users/wouterlefebvre/Github Repo's/FaceRec/FaceRecVenv/lib/python3.6/site-packages/sqlalchemy/orm/query.py", line 3325, in one
    ret = self.one_or_none()
  File "/Users/wouterlefebvre/Github Repo's/FaceRec/FaceRecVenv/lib/python3.6/site-packages/sqlalchemy/orm/query.py", line 3294, in one_or_none
    ret = list(self)
  File "/Users/wouterlefebvre/Github Repo's/FaceRec/FaceRecVenv/lib/python3.6/site-packages/sqlalchemy/orm/query.py", line 3367, in __iter__
    return self._execute_and_instances(context)
  File "/Users/wouterlefebvre/Github Repo's/FaceRec/FaceRecVenv/lib/python3.6/site-packages/sqlalchemy/orm/query.py", line 3389, in _execute_and_instances
    querycontext, self._connection_from_session, close_with_result=True
  File "/Users/wouterlefebvre/Github Repo's/FaceRec/FaceRecVenv/lib/python3.6/site-packages/sqlalchemy/orm/query.py", line 3404, in _get_bind_args
    mapper=self._bind_mapper(), clause=querycontext.statement, **kw
  File "/Users/wouterlefebvre/Github Repo's/FaceRec/FaceRecVenv/lib/python3.6/site-packages/sqlalchemy/orm/query.py", line 3382, in _connection_from_session
    conn = self.session.connection(**kw)
  File "/Users/wouterlefebvre/Github Repo's/FaceRec/FaceRecVenv/lib/python3.6/site-packages/sqlalchemy/orm/session.py", line 1133, in connection
    execution_options=execution_options,
  File "/Users/wouterlefebvre/Github Repo's/FaceRec/FaceRecVenv/lib/python3.6/site-packages/sqlalchemy/orm/session.py", line 1139, in _connection_for_bind
    engine, execution_options
  File "/Users/wouterlefebvre/Github Repo's/FaceRec/FaceRecVenv/lib/python3.6/site-packages/sqlalchemy/orm/session.py", line 432, in _connection_for_bind
    conn = bind._contextual_connect()
  File "/Users/wouterlefebvre/Github Repo's/FaceRec/FaceRecVenv/lib/python3.6/site-packages/sqlalchemy/engine/base.py", line 2242, in _contextual_connect
    self._wrap_pool_connect(self.pool.connect, None),
  File "/Users/wouterlefebvre/Github Repo's/FaceRec/FaceRecVenv/lib/python3.6/site-packages/sqlalchemy/engine/base.py", line 2280, in _wrap_pool_connect
    e, dialect, self
  File "/Users/wouterlefebvre/Github Repo's/FaceRec/FaceRecVenv/lib/python3.6/site-packages/sqlalchemy/engine/base.py", line 1547, in _handle_dbapi_exception_noconnection
    util.raise_from_cause(sqlalchemy_exception, exc_info)
  File "/Users/wouterlefebvre/Github Repo's/FaceRec/FaceRecVenv/lib/python3.6/site-packages/sqlalchemy/util/compat.py", line 398, in raise_from_cause
    reraise(type(exception), exception, tb=exc_tb, cause=cause)
  File "/Users/wouterlefebvre/Github Repo's/FaceRec/FaceRecVenv/lib/python3.6/site-packages/sqlalchemy/util/compat.py", line 152, in reraise
    raise value.with_traceback(tb)
  File "/Users/wouterlefebvre/Github Repo's/FaceRec/FaceRecVenv/lib/python3.6/site-packages/sqlalchemy/engine/base.py", line 2276, in _wrap_pool_connect
    return fn()
  File "/Users/wouterlefebvre/Github Repo's/FaceRec/FaceRecVenv/lib/python3.6/site-packages/sqlalchemy/pool/base.py", line 363, in connect
    return _ConnectionFairy._checkout(self)
  File "/Users/wouterlefebvre/Github Repo's/FaceRec/FaceRecVenv/lib/python3.6/site-packages/sqlalchemy/pool/base.py", line 760, in _checkout
    fairy = _ConnectionRecord.checkout(pool)
  File "/Users/wouterlefebvre/Github Repo's/FaceRec/FaceRecVenv/lib/python3.6/site-packages/sqlalchemy/pool/base.py", line 492, in checkout
    rec = pool._do_get()
  File "/Users/wouterlefebvre/Github Repo's/FaceRec/FaceRecVenv/lib/python3.6/site-packages/sqlalchemy/pool/impl.py", line 139, in _do_get
    self._dec_overflow()
  File "/Users/wouterlefebvre/Github Repo's/FaceRec/FaceRecVenv/lib/python3.6/site-packages/sqlalchemy/util/langhelpers.py", line 68, in __exit__
    compat.reraise(exc_type, exc_value, exc_tb)
  File "/Users/wouterlefebvre/Github Repo's/FaceRec/FaceRecVenv/lib/python3.6/site-packages/sqlalchemy/util/compat.py", line 153, in reraise
    raise value
  File "/Users/wouterlefebvre/Github Repo's/FaceRec/FaceRecVenv/lib/python3.6/site-packages/sqlalchemy/pool/impl.py", line 136, in _do_get
    return self._create_connection()
  File "/Users/wouterlefebvre/Github Repo's/FaceRec/FaceRecVenv/lib/python3.6/site-packages/sqlalchemy/pool/base.py", line 308, in _create_connection
    return _ConnectionRecord(self)
  File "/Users/wouterlefebvre/Github Repo's/FaceRec/FaceRecVenv/lib/python3.6/site-packages/sqlalchemy/pool/base.py", line 437, in __init__
    self.__connect(first_connect_check=True)
  File "/Users/wouterlefebvre/Github Repo's/FaceRec/FaceRecVenv/lib/python3.6/site-packages/sqlalchemy/pool/base.py", line 639, in __connect
    connection = pool._invoke_creator(self)
  File "/Users/wouterlefebvre/Github Repo's/FaceRec/FaceRecVenv/lib/python3.6/site-packages/sqlalchemy/engine/strategies.py", line 114, in connect
    return dialect.connect(*cargs, **cparams)
  File "/Users/wouterlefebvre/Github Repo's/FaceRec/FaceRecVenv/lib/python3.6/site-packages/sqlalchemy/engine/default.py", line 482, in connect
    return self.dbapi.connect(*cargs, **cparams)
sqlalchemy.exc.OperationalError: (pyodbc.OperationalError) ('HYT00', '[HYT00] [Microsoft][ODBC Driver 13 for SQL Server]Login timeout expired (0) (SQLDriverConnect)')
(Background on this error at: http://sqlalche.me/e/e3q8)
