2020-01-17 08:54:42,090 ERROR: Exception on / [GET] [in /Users/wouterlefebvre/Github Repo's/FaceRec/FaceRecVenv/lib/python3.6/site-packages/flask/app.py:1891]
Traceback (most recent call last):
  File "/Users/wouterlefebvre/Github Repo's/FaceRec/FaceRecVenv/lib/python3.6/site-packages/sqlalchemy/util/_collections.py", line 1010, in __call__
    return self.registry[key]
KeyError: 123145522364416

During handling of the above exception, another exception occurred:

Traceback (most recent call last):
  File "/Users/wouterlefebvre/Github Repo's/FaceRec/FaceRecVenv/lib/python3.6/site-packages/flask/app.py", line 2446, in wsgi_app
    response = self.full_dispatch_request()
  File "/Users/wouterlefebvre/Github Repo's/FaceRec/FaceRecVenv/lib/python3.6/site-packages/flask/app.py", line 1951, in full_dispatch_request
    rv = self.handle_user_exception(e)
  File "/Users/wouterlefebvre/Github Repo's/FaceRec/FaceRecVenv/lib/python3.6/site-packages/flask/app.py", line 1820, in handle_user_exception
    reraise(exc_type, exc_value, tb)
  File "/Users/wouterlefebvre/Github Repo's/FaceRec/FaceRecVenv/lib/python3.6/site-packages/flask/_compat.py", line 39, in reraise
    raise value
  File "/Users/wouterlefebvre/Github Repo's/FaceRec/FaceRecVenv/lib/python3.6/site-packages/flask/app.py", line 1949, in full_dispatch_request
    rv = self.dispatch_request()
  File "/Users/wouterlefebvre/Github Repo's/FaceRec/FaceRecVenv/lib/python3.6/site-packages/flask/app.py", line 1935, in dispatch_request
    return self.view_functions[rule.endpoint](**req.view_args)
  File "/Users/wouterlefebvre/Github Repo's/FaceRec/application/routes.py", line 111, in index
    return render_template('index.html')
  File "/Users/wouterlefebvre/Github Repo's/FaceRec/FaceRecVenv/lib/python3.6/site-packages/flask/templating.py", line 136, in render_template
    ctx.app.update_template_context(context)
  File "/Users/wouterlefebvre/Github Repo's/FaceRec/FaceRecVenv/lib/python3.6/site-packages/flask/app.py", line 838, in update_template_context
    context.update(func())
  File "/Users/wouterlefebvre/Github Repo's/FaceRec/FaceRecVenv/lib/python3.6/site-packages/flask_login/utils.py", line 368, in _user_context_processor
    return dict(current_user=_get_user())
  File "/Users/wouterlefebvre/Github Repo's/FaceRec/FaceRecVenv/lib/python3.6/site-packages/flask_login/utils.py", line 335, in _get_user
    current_app.login_manager._load_user()
  File "/Users/wouterlefebvre/Github Repo's/FaceRec/FaceRecVenv/lib/python3.6/site-packages/flask_login/login_manager.py", line 353, in _load_user
    return self._load_from_cookie(request.cookies[cookie_name])
  File "/Users/wouterlefebvre/Github Repo's/FaceRec/FaceRecVenv/lib/python3.6/site-packages/flask_login/login_manager.py", line 392, in _load_from_cookie
    self.reload_user()
  File "/Users/wouterlefebvre/Github Repo's/FaceRec/FaceRecVenv/lib/python3.6/site-packages/flask_login/login_manager.py", line 321, in reload_user
    user = self.user_callback(user_id)
  File "/Users/wouterlefebvre/Github Repo's/FaceRec/application/models.py", line 23, in load_user
    return User.query.get(int(id))
  File "/Users/wouterlefebvre/Github Repo's/FaceRec/FaceRecVenv/lib/python3.6/site-packages/flask_sqlalchemy/__init__.py", line 519, in __get__
    return type.query_class(mapper, session=self.sa.session())
  File "/Users/wouterlefebvre/Github Repo's/FaceRec/FaceRecVenv/lib/python3.6/site-packages/sqlalchemy/orm/scoping.py", line 78, in __call__
    return self.registry()
  File "/Users/wouterlefebvre/Github Repo's/FaceRec/FaceRecVenv/lib/python3.6/site-packages/sqlalchemy/util/_collections.py", line 1012, in __call__
    return self.registry.setdefault(key, self.createfunc())
  File "/Users/wouterlefebvre/Github Repo's/FaceRec/FaceRecVenv/lib/python3.6/site-packages/sqlalchemy/orm/session.py", line 3234, in __call__
    return self.class_(**local_kw)
  File "/Users/wouterlefebvre/Github Repo's/FaceRec/FaceRecVenv/lib/python3.6/site-packages/flask_sqlalchemy/__init__.py", line 138, in __init__
    bind = options.pop('bind', None) or db.engine
  File "/Users/wouterlefebvre/Github Repo's/FaceRec/FaceRecVenv/lib/python3.6/site-packages/flask_sqlalchemy/__init__.py", line 937, in engine
    return self.get_engine()
  File "/Users/wouterlefebvre/Github Repo's/FaceRec/FaceRecVenv/lib/python3.6/site-packages/flask_sqlalchemy/__init__.py", line 956, in get_engine
    return connector.get_engine()
  File "/Users/wouterlefebvre/Github Repo's/FaceRec/FaceRecVenv/lib/python3.6/site-packages/flask_sqlalchemy/__init__.py", line 561, in get_engine
    self._engine = rv = self._sa.create_engine(sa_url, options)
  File "/Users/wouterlefebvre/Github Repo's/FaceRec/FaceRecVenv/lib/python3.6/site-packages/flask_sqlalchemy/__init__.py", line 966, in create_engine
    return sqlalchemy.create_engine(sa_url, **engine_opts)
  File "/Users/wouterlefebvre/Github Repo's/FaceRec/FaceRecVenv/lib/python3.6/site-packages/sqlalchemy/engine/__init__.py", line 479, in create_engine
    return strategy.create(*args, **kwargs)
  File "/Users/wouterlefebvre/Github Repo's/FaceRec/FaceRecVenv/lib/python3.6/site-packages/sqlalchemy/engine/strategies.py", line 87, in create
    dbapi = dialect_cls.dbapi(**dbapi_args)
  File "/Users/wouterlefebvre/Github Repo's/FaceRec/FaceRecVenv/lib/python3.6/site-packages/sqlalchemy/connectors/pyodbc.py", line 37, in dbapi
    return __import__("pyodbc")
ModuleNotFoundError: No module named 'pyodbc'
2020-01-17 08:54:58,843 INFO: website startup [in /Users/wouterlefebvre/Github Repo's/FaceRec/application/__init__.py:38]
